Workbook
Name _56F9DC9755BA473782653E2940F9FormId: "y3yDDp4oxEWPHuKDu39iiayg-uvPrSNIj-BFIIWav09UODMwT01LNUxOSkIxV0VHVTJBWTBJWjg4TyQlQCN0PWcu"
Name _56F9DC9755BA473782653E2940F9ResponseSheet: "Form1"
Name _56F9DC9755BA473782653E2940F9SourceDocId: "{e252a9d9-c8f5-445e-aad5-a4445655d22e}"
Name StepNo: !A1048576+1

Sheet SR History
A2: SR History | H2: BBK | I2: 10972 | K2: 0994000160151 | M2: กรุงเทพมหานคร | O2: 7 | P2: ค่าขยะ
A3: PROJECT/SR CODE | B3: Test Date | C3: Version | D3: รายละเอียด | E3: Mandays | F3: ผู้ทดสอบ | G3: Remark | H3: Solution ในการพัฒนาระบบ | I3: OR | J3: REPRINT | K3: UPLOAD | L3: DEL-UPLOAD | M3: MIN | N3: MAX | O3: ค่าบริการ กรุงเทพ | P3: ค่าบริการ ต่างจังหวัด | Q3: CHK_AMT | R3: check Dup
A4: CP ALL GROUP-2025/03746 | B4: 244236 | C4: 25009A | D4: New Client 10972_กรุงเทพมหานคร (Owner AE : Thanat-On N. / BA : Arreeya S. , Channel : POS, SAMEDAY, BACKEND) - Service 01-50 ชำระค่าขยะ - ระบบ Full online - Memo : CS-BUD3 642/2568 - มีผลวันที่ 28 สิงหาคม 2568 - อ้างอิงเอกสาร => 10972_กรุงเทพมหานครV0.4.xlsx | E4: 2 MD | F4: Nakarin S. | G4: New Full | H4: Full Online | I4: 10800 | J4: 0 | K4: N | L4: N | M4: 1 | N4: 90000 | O4: 10,20 | P4: 10,21 | Q4: ไม่รองรับทศนิยม | R4: Online Check

Sheet Test_Case&Result
A1: TEST CASES & RESULT
A2: TEST DESCRIPTION | G2: TEST ENVIRONMENT | K2: Priority Type | L2: Count Priority
A3: PROJECT/SR CODE: | D3: =Option!A2 -> CP ALL GROUP-2025/03746 | G3: TEST ENVIRONMENT ID: | K3: Priority - 1 | L3: =COUNTIF(C17:C1000,"P1") -> 75
A4: PROJECT NAME/ SR DETAIL: | D4: ="ทดสอบ Online Version "&Option!C2 -> ทดสอบ Online Version 25009A | G4: ENVIRONMENT: | K4: Priority - 2 | L4: =COUNTIF(C17:C1000,"P2") -> 0
A5: TEST PHASE: | D5: Integration | E5: OTHERS : | G5: PC/NOTEBOOK CAPABILITIES:SimulatorWAS7V25 V15.0.0.0 | H5: Memory: | J5: Harddisk: | K5: Priority - 3 | L5: =COUNTIF(C17:C1000,"P3") -> 0
A6: TEST CASE NO.: | D6: ="ONL_V"&Option!C2 -> ONL_V25009A | E6: VERSION : | F6: =COUNTA('SR History'!A:A)-2 -> 1 | G6: CPU Speed: | H6: Others
A7: TEST CASE NAME : | D7: ="QCM-COU-Test Case&Result_CS Online_"&'SR History'!I2&"_SV"&'SR History'!O2&"_"&'SR History'!H2&"-R1.xlsx" -> QCM-COU-Test Case&Result_CS Online_10972_SV7_BBK-R1.xlsx | G7: SERVER CAPABILITIES:Toad for Oracle 9.0.1 | H7: Memory: | J7: Harddisk:Harddisk: 7.48 MB
A8: TEST OBJECTIVE: | D8: โปรแกรมสามารถทำงานได้ถูกต้องตามเงื่อนไข Requirement | G8: CPU Speed: | H8: Others
A9: TEST DATE: | D9: =Option!B2 -> 244236 | E9: NUMBER OF TESTING ROUND: | F9: 1 | G9: DATABASE CAPABILITIES: | H9: Memory: | J9: Harddisk:
A10: PRE-CONDITION: | D10: ทดสอบบน Simulator SimulatorWAS7V25THAI.exe IP : testcspos.counterservice.co.th WS ADDRESS : /DCWSCDSONLINE/WSCDSService PORT : 8001 | G10: CPU Speed: | H10: Others
A11: SPECIAL NOTES: | G11: TEST DATA (Location): ร้านทดสอบ 09884
A12: REFERENCE DOCUMENTS : | D12: =Option!D2 -> New Client 10972_กรุงเทพมหานคร (Owner AE : Thanat-On N. / BA : Arreeya S. , Channel : POS, SAMEDAY, BACKEND) - Service 01-50 ชำระค่าขยะ - ระบบ Full online - Memo : CS-BUD3 642/2568 - มีผลวันที่ 28 สิงหาคม 2568 - อ้างอิงเอกสาร => 10972_กรุงเทพมหานครV0.4.xlsx | G12: OS : NoteBook > System type 32 - bit operating System Microsoft Windows 7 Professional
A13: TOTAL TIME USED TO EXECUTE THIS TEST CASE: | D13: =Option!E2 -> 2 MD | G13: WEB BROWSER : Internet Explorer 8, Google Chrome เวอร์ชัน 62.0.3202.94 (32 บิต)
A14: PREPARED BY: | D14: =Option!F2 -> Nakarin S. | E14: REVIEWED BY: | F14: Piyanooch W.
A16: ตรวจสอบ | B16: ='SR History'!M2 -> กรุงเทพมหานคร | E16: ="Client ID : "&'SR History'!I2 -> Client ID : 10972 | F16: ="Tax ID :"&'SR History'!K2 -> Tax ID :0994000160151
A17: ="Service "&'SR History'!O2&" : "&'SR History'!P2 -> Service 7 : ค่าขยะ
A18: Step No | B18: Updated | C18: VP | D18: Test case / script | E18: Data | F18: Expected Results | G18: Actual Results | H18: Test Status | I18: Results | J18: Reproduct/Remark
A19: =IF((C19)="","",MAX($A$2:A18)+1) -> 1 | B19: =IF((C19)="","",$D$9) -> 244236 | C19: P1 | D19: ตรวจสอบการกำหนดค่า ระยะเวลาที่สามารถทำรายการ OR ได้ ที่ DB ONLSTD TBL = WS_CLIENT_CONFIG | F19: อ้างอิง ROW ที่ VENDOR_ID = Tax_ID ของผวจ.ดังกล่าว SERVICE_ID = รหัส Service ของผวจ.ดังกล่าว - ที่ Field OR_TIMEOUT = ระยะเวลาหลัง Confirm รายการ/วินาที | G19: ="อ้างอิง ROW ที่ VENDOR_ID = Tax_ID ของผวจ.ดังกล่าว SERVICE_ID = รหัส Service ของผวจ.ดังกล่าว - ที่ Field OR_TIMEOUT = "&Option!I2 -> อ้างอิง ROW ที่ VENDOR_ID = Tax_ID ของผวจ.ดังกล่าว SERVICE_ID = รหัส Service ของผวจ.ดังกล่าว - ที่ Field OR_TIMEOUT = 10800 | H19: Pass
A20: =IF((C20)="","",MAX($A$2:A19)+1) -> 2 | B20: =IF((C20)="","",$D$9) -> 244236 | C20: P1 | D20: ตรวจสอบการกำหนดค่า ยอดเงินต่ำสุดที่สามารถรับชำระได้ ที่ DB ONLSTD TBL = WS_CLIENT_CONFIG | F20: อ้างอิง ROW ที่ VENDOR_ID = Tax_ID ของผวจ.ดังกล่าว SERVICE_ID = รหัส Service ของผวจ.ดังกล่าว - ที่ Field MIN_AMT = จำนวนเงินต่ำสุดที่สามารถรับชำระได้ | G20: ="อ้างอิง ROW ที่ VENDOR_ID = Tax_ID ของผวจ.ดังกล่าว SERVICE_ID = รหัส Service ของผวจ.ดังกล่าว - ที่ Field MIN_AMT = "&Option!M2 -> อ้างอิง ROW ที่ VENDOR_ID = Tax_ID ของผวจ.ดังกล่าว SERVICE_ID = รหัส Service ของผวจ.ดังกล่าว - ที่ Field MIN_AMT = 1 | H20: Pass
A21: =IF((C21)="","",MAX($A$2:A20)+1) -> 3 | B21: =IF((C21)="","",$D$9) -> 244236 | C21: P1 | D21: ตรวจสอบการกำหนดค่า ยอดเงินต่ำสุดที่สามารถรับชำระได้ ที่ DB ONLSTD TBL = WS_CLIENT_CONFIG | F21: อ้างอิง ROW ที่ VENDOR_ID = Tax_ID ของผวจ.ดังกล่าว SERVICE_ID = รหัส Service ของผวจ.ดังกล่าว - ที่ Field MAX_AMT = กำหนดจำนวนเงินสูงสุดที่สามารถรับชำระได้ | G21: ="อ้างอิง ROW ที่ VENDOR_ID = Tax_ID ของผวจ.ดังกล่าว SERVICE_ID = รหัส Service ของผวจ.ดังกล่าว - ที่ Field MAX_AMT = "&Option!N2 -> อ้างอิง ROW ที่ VENDOR_ID = Tax_ID ของผวจ.ดังกล่าว SERVICE_ID = รหัส Service ของผวจ.ดังกล่าว - ที่ Field MAX_AMT = 90000 | H21: Pass
A22: =IF((C22)="","",MAX($A$2:A21)+1) -> 4 | B22: =IF((C22)="","",$D$9) -> 244236 | C22: P1 | D22: ตรวจสอบการกำหนดรูปแบบการคิดค่าบริการ ที่ DB ONLSTD TBL = WS_CLIENT_CONFIG | F22: ที่ VENDOR_ID = Tax_ID ของผวจ.ดังกล่าว SERVICE_ID = รหัส Service ของผวจ.ดังกล่าว - ที่ Field SERVICE_CHARGE = กำหนดรูปแบบการคิดค่าบริการ 1 หมายถึง กำหนดค่าบริการตาม WS_CLIENT_CHARGE 2 หมายถึง กำหนดค่าบริการเป็นขั้นตาม WS_CLIENT_CHARGE_STEP 3 หมายถึง กำหนดค่าบริการเป็นขั้นตาม WS_CLIENT_CHARGE_STEP เหมือนกัน แต่เอาค่าเงินที่ได้จากตอนที่ ผวจ. ตอบกลับมา มาคิดว่าอยู่ในช่วงไหน 4 หมายถึง คิดค่าบริการแบบรวม แต่ละ transaction N หมายถึง ไม่คิดค่าบริการ M หมายถึง รองรับค่าบริการแบบว่าส่งหลาย ๆ Vendor กลับไปหาร้าน | G22: ="อ้างอิง ROW ที่ VENDOR_ID = Tax_ID ของผวจ.ดังกล่าว SERVICE_ID=รหัส Service ของผวจ.ดังกล่าว - ที่ Field SERVICE_CHARGE = "&VLOOKUP(I22,Option!A11:B16,2,FALSE) -> อ้างอิง ROW ที่ VENDOR_ID = Tax_ID ของผวจ.ดังกล่าว SERVICE_ID=รหัส Service ของผวจ.ดังกล่าว - ที่ Field SERVICE_CHARGE = 2 หมายถึง กำหนดค่าบริการเป็นขั้นตาม WS_CLIENT_CHARGE_STEP | H22: Pass | I22: 2
A23: =IF((C23)="","",MAX($A$2:A22)+1) -> 5 | B23: =IF((C23)="","",$D$9) -> 244236 | C23: P1 | D23: ตรวจสอบการกำหนดค่า Solution ในการพัฒนาระบบ ที่ DB ONLSTD TBL = WS_CLIENT_CONFIG | F23: อ้างอิง ROW ที่ VENDOR_ID = Tax_ID ของผวจ.ดังกล่าว SERVICE_ID = รหัส Service ของผวจ.ดังกล่าว - ที่ Field SYSTEM_TYPE = Solution ในการพัฒนาระบบ F มาจาก Full H มาจาก Half ตำแหน่งแรก จะหมายถึงขา Exchange ตำแหน่งสองจะหมายถึงขา Confirm F หมายถึงมีการเรียกมาถึง step ที่ config url ไว้ H หมายถึงไม่มีการเรียก config url | G23: ="อ้างอิง ROW ที่ VENDOR_ID = Tax_ID ของผวจ.ดังกล่าว SERVICE_ID = รหัส Service ของผวจ.ดังกล่าว - ที่ Field SYSTEM_TYPE = "&I23 -> อ้างอิง ROW ที่ VENDOR_ID = Tax_ID ของผวจ.ดังกล่าว SERVICE_ID = รหัส Service ของผวจ.ดังกล่าว - ที่ Field SYSTEM_TYPE = FF | H23: Pass | I23: FF
A24: =IF((C24)="","",MAX($A$2:A23)+1) -> 6 | B24: =IF((C24)="","",$D$9) -> 244236 | C24: P1 | D24: ตรวจสอบ "แก้ไขจำนวนเงิน" ที่ DB ONLSTD TBL = WS_CLIENT_CONFIG | F24: อ้างอิง ROW ที่ VENDOR_ID = Tax_ID ของผวจ.ดังกล่าว SERVICE_ID = รหัส Service ของผวจ.ดังกล่าว - ที่ Field "PARTAIL_AMT = กำหนดแก้ไขเงินได้หรือไม่" Y = แก้ไขเงินได้ N = แก้ไขเงินไม่ได้ | G24: ="อ้างอิง ROW ที่ VENDOR_ID = Tax_ID ของผวจ.ดังกล่าว SERVICE_ID = รหัส Service ของผวจ.ดังกล่าว - ที่ Field PARTAIL_AMT = "&I24 -> อ้างอิง ROW ที่ VENDOR_ID = Tax_ID ของผวจ.ดังกล่าว SERVICE_ID = รหัส Service ของผวจ.ดังกล่าว - ที่ Field PARTAIL_AMT = N | H24: Pass | I24: N
A25: =IF((C25)="","",MAX($A$2:A24)+1) -> 7 | B25: =IF((C25)="","",$D$9) -> 244236 | C25: P1 | D25: ตรวจสอบ เช็คเงิน"ก่อน"ส่งไปถึงผู้ว่าจ้าง" ที่ DB ONLSTD TBL = WS_CLIENT_CONFIG | F25: อ้างอิง ROW ที่ VENDOR_ID = Tax_ID ของผวจ.ดังกล่าว SERVICE_ID = รหัส Service ของผวจ.ดังกล่าว - ที่ Field "CHK_AMT_BEFORE = เช็คเงิน"ก่อน"ส่งไปถึงผู้ว่าจ้าง" Y = เช็คเงิน"ก่อน"ส่งไปถึงผู้ว่าจ้าง N = ไม่เช็คเงิน"ก่อน"ส่งไปถึงผู้ว่าจ้าง | G25: ="อ้างอิง ROW ที่ VENDOR_ID = Tax_ID ของผวจ.ดังกล่าว SERVICE_ID = รหัส Service ของผวจ.ดังกล่าว - ที่ Field CHK_AMT_BEFORE = "&I25 -> อ้างอิง ROW ที่ VENDOR_ID = Tax_ID ของผวจ.ดังกล่าว SERVICE_ID = รหัส Service ของผวจ.ดังกล่าว - ที่ Field CHK_AMT_BEFORE = Y | H25: Pass | I25: Y
A26: =IF((C26)="","",MAX($A$2:A25)+1) -> 8 | B26: =IF((C26)="","",$D$9) -> 244236 | C26: P1 | D26: ตรวจสอบเช็คเงิน"หลัง"ส่งไปถึงผู้ว่าจ้าง" ที่ DB ONLSTD TBL = WS_CLIENT_CONFIG | F26: อ้างอิง ROW ที่ VENDOR_ID = Tax_ID ของผวจ.ดังกล่าว SERVICE_ID = รหัส Service ของผวจ.ดังกล่าว - ที่ Field "CHK_AMT_AFTER = เช็คเงิน"หลัง"ส่งไปถึงผู้ว่าจ้าง" Y = เช็คเงิน"หลัง"ส่งไปถึงผู้ว่าจ้าง N = ไม่เช็คเงิน"หลัง"ส่งไปถึงผู้ว่าจ้าง | G26: ="อ้างอิง ROW ที่ VENDOR_ID = Tax_ID ของผวจ.ดังกล่าว SERVICE_ID = รหัส Service ของผวจ.ดังกล่าว - ที่ Field CHK_AMT_AFTER = "&I26 -> อ้างอิง ROW ที่ VENDOR_ID = Tax_ID ของผวจ.ดังกล่าว SERVICE_ID = รหัส Service ของผวจ.ดังกล่าว - ที่ Field CHK_AMT_AFTER = N | H26: Pass | I26: N
A27: =IF((C27)="","",MAX($A$2:A26)+1) -> 9 | B27: =IF((C27)="","",$D$9) -> 244236 | C27: P1 | D27: ตรวจสอบ "เช็ค"ทศนิยม"" ที่ DB ONLSTD TBL = WS_CLIENT_CONFIG | F27: อ้างอิง ROW ที่ VENDOR_ID = Tax_ID ของผวจ.ดังกล่าว SERVICE_ID = รหัส Service ของผวจ.ดังกล่าว - ที่ Field "CHK_AMT_FNT = เช็คทศนิยม" 1 = "ไม่"รองรับทศนิยม รับเฉพาะ 0.00 เท่านั้น 2 = รองรับ"ลงตัว" 0.00 , 0.25, 0.50 , 0.75 N = รองรับทศนิยม "ไม่" ลงตัว 0.00,0.01,...0.99 หมายเหตุ 1 HALF ONLINE (CHK_AMT_FNT = N) เสมอ เพราะให้ CS หน้าร้านเช็ค ทศนิยม 2 HALF ONLINE (CHK_AMT_FNT = 1,2,N) **จะเช็คเงื่อนไขนี้** | G27: ="อ้างอิง ROW ที่ VENDOR_ID = Tax_ID ของผวจ.ดังกล่าว SERVICE_ID = รหัส Service ของผวจ.ดังกล่าว - ที่ Field CHK_AMT_FNT = เช็คทศนิยม "& IF(I27="N","N = รองรับทศนิยม ไม่ ลงตัว 0.00,0.01,...0.99",IF(I27="2","2 = รองรับลงตัว 0.00 , 0.25, 0.50 , 0.75","1 = ไม่รองรับทศนิยม รับเฉพาะ 0.00 เท่านั้น")) -> อ้างอิง ROW ที่ VENDOR_ID = Tax_ID ของผวจ.ดังกล่าว SERVICE_ID = รหัส Service ของผวจ.ดังกล่าว - ที่ Field CHK_AMT_FNT = เช็คทศนิยม 1 = ไม่รองรับทศนิยม รับเฉพาะ 0.00 เท่านั้น | H27: Pass | I27: 2
A28: =IF((C28)="","",MAX($A$2:A27)+1) -> 10 | B28: =IF((C28)="","",$D$9) -> 244236 | C28: P1 | D28: ตรวจสอบการกำหนดค่า ค่าบริการแบบคิดจากพื้นที่ ที่ DB ONLSTD TBL = WS_CLIENT_CHARGE | F28: อ้างอิง ROW ที่ VENDOR_ID = Tax_ID ของผวจ.ดังกล่าว SERVICE_ID = รหัส Service ของผวจ.ดังกล่าว - ที่ Field SERVICE_CHARGE_CENTRE = ค่าบริการในเขตกทม. | G28: ="อ้างอิง ROW ที่ VENDOR_ID = Tax_ID ของผวจ.ดังกล่าว SERVICE_ID = รหัส Service ของผวจ.ดังกล่าว - ที่ Field SERVICE_CHARGE_CENTRE = "&Option!O2 -> อ้างอิง ROW ที่ VENDOR_ID = Tax_ID ของผวจ.ดังกล่าว SERVICE_ID = รหัส Service ของผวจ.ดังกล่าว - ที่ Field SERVICE_CHARGE_CENTRE = 10,20 | H28: Pass
A29: =IF((C29)="","",MAX($A$2:A28)+1) -> 11 | B29: =IF((C29)="","",$D$9) -> 244236 | C29: P1 | D29: ตรวจสอบการกำหนดค่า ค่าบริการแบบคิดจากพื้นที่ ที่ DB ONLSTD TBL = WS_CLIENT_CHARGE | F29: อ้างอิง ROW ที่ VENDOR_ID = Tax_ID ของผวจ.ดังกล่าว SERVICE_ID = รหัส Service ของผวจ.ดังกล่าว - ที่ Field SERVICE_CHARGE_PROVINCESE = ค่าบริการในเขตตจว. | G29: ="อ้างอิง ROW ที่ VENDOR_ID = Tax_ID ของผวจ.ดังกล่าว SERVICE_ID = รหัส Service ของผวจ.ดังกล่าว - ที่ Field SERVICE_CHARGE_PROVINCESE = "&Option!P2 -> อ้างอิง ROW ที่ VENDOR_ID = Tax_ID ของผวจ.ดังกล่าว SERVICE_ID = รหัส Service ของผวจ.ดังกล่าว - ที่ Field SERVICE_CHARGE_PROVINCESE = 10,21 | H29: Pass
A30: =IF((C30)="","",MAX($A$2:A27)+1) -> 10 | B30: =IF((C30)="","",$D$9) -> 244236 | C30: P0 | D30: ตรวจสอบการกำหนดค่า ค่าบริการแบบคิดเป็น Step ตามยอดเงินที่รับชำระ ที่ DB ONLSTD TBL = WS_CLIENT_CHARGE_STEP | F30: อ้างอิง ROW ที่ VENDOR_ID = Tax_ID ของผวจ.ดังกล่าว SERVICE_ID = รหัส Service ของผวจ.ดังกล่าว - ที่ Field WS_CLIENT_CHARGE_STEP = ค่าบริการในเขตกทม. | G30: ไม่มีการกำหนดค่า WS_CLIENT_CHARGE_STEP | H30: Pass
A31: =IF((C31)="","",MAX($A$2:A28)+1) -> 11 | B31: =IF((C31)="","",$D$9) -> 244236 | C31: P1 | D31: ตรวจสอบการกำหนดค่า ค่าบริการแบบคิดเป็น Step ตามยอดเงินที่รับชำระ ที่ DB ONLSTD TBL = WS_CLIENT_CHARGE_STEP | F31: อ้างอิง ROW ที่ VENDOR_ID = Tax_ID ของผวจ.ดังกล่าว SERVICE_ID = รหัส Service ของผวจ.ดังกล่าว - ที่ Field WS_CLIENT_CHARGE_STEP = ค่าบริการในเขตตจว. | G31: ไม่มีการกำหนดค่า WS_CLIENT_CHARGE_STEP | H31: Pass
A32: =IF((C32)="","",MAX($A$2:A31)+1) -> 12 | B32: =IF((C32)="","",$D$9) -> 244236 | C32: P1 | D32: ตรวจสอบการกำหนดค่า AutoFix ที่ TBL WS_CLIENT_AUTOFIXTX | F32: มีการกำหนดค่า AutoFix ได้ถูกต้อง - ที่ Field SERVER_RUN = rac5Job2 | G32: ="มีการกำหนดค่า AutoFix ได้ถูกต้อง - ที่ Field SERVER_RUN = "&I32 -> มีการกำหนดค่า AutoFix ได้ถูกต้อง - ที่ Field SERVER_RUN = rac5Job2 | H32: Pass | I32: rac5Job2
A33: =IF((C33)="","",MAX($A$2:A32)+1) -> 13 | B33: =IF((C33)="","",$D$9) -> 244236 | C33: P1 | D33: ตรวจสอบการกำหนดค่า Error Code ที่ DB ONLSTD TBL = WS_STD_ERROR_CODE | F33: ไม่มีการกำหนดค่า Error Code และใช้ Error Code standard | G33: =I33&"การกำหนดค่า Error Code และใช้ Error Code standard" -> ไม่มีการกำหนดค่า Error Code และใช้ Error Code standard | H33: Pass | I33: ไม่มี
A34: =IF((C34)="","",MAX($A$2:A33)+1) -> 14 | B34: =IF((C34)="","",$D$9) -> 244236 | C34: P1 | D34: ตรวจสอบการกำหนดค่า Reprint ที่ DB ONLSTD TBL WS_CLIENT_REPRINT | F34: ไม่มีการกำหนดค่าที่ DB ONLSTD TBL WS_CLIENT_REPRINT | G34: =I34&"การกำหนดค่าที่ DB ONLSTD TBL WS_CLIENT_REPRINT" -> ไม่มีการกำหนดค่าที่ DB ONLSTD TBL WS_CLIENT_REPRINT | H34: Pass | I34: ไม่มี
A35: =IF((C35)="","",MAX($A$2:A34)+1) -> 15 | B35: =IF((C35)="","",$D$9) -> 244236 | C35: P1 | D35: ตรวจสอบการกำหนดค่า SERVICE_ADDRESS ที่ DB ONLSTD TBL = WS_STD_SERVICE_LOOKUP | F35: ไม่มีการกำหนดค่าที่ DB ONLSTD TBL = WS_STD_SERVICE_LOOKUP | G35: =I35&"การกำหนดค่าที่ DB ONLSTD TBL = WS_STD_SERVICE_LOOKUP" -> ไม่มีการกำหนดค่าที่ DB ONLSTD TBL = WS_STD_SERVICE_LOOKUP | H35: Pass | I35: ไม่มี
A36: =IF((C36)="","",MAX($A$2:A35)+1) -> 16 | B36: =IF((C36)="","",$D$9) -> 244236 | C36: P1 | D36: ตรวจสอบการกำหนดค่า Return ที่ DB ONLSTD TBL WS_CLIENT_RETURN | F36: ไม่มีการกำหนดค่าที่ DB ONLSTD TBL WS_CLIENT_RETURN | G36: =I36&"การกำหนดค่าที่ DB ONLSTD TBL WS_CLIENT_RETURN" -> ไม่มีการกำหนดค่าที่ DB ONLSTD TBL WS_CLIENT_RETURN | H36: Pass | I36: ไม่มี
A37: =IF((C37)="","",MAX($A$2:A36)+1) -> 17 | B37: =IF((C37)="","",$D$9) -> 244236 | C37: P1 | D37: ตรวจสอบการกำหนดค่า Return ที่ DB ONLSTD TBL WS_CLIENT_RETURN_LEN_EXTEN | F37: ไม่มีการกำหนดค่าที่ DB ONLSTD TBL WS_CLIENT_RETURN_LEN_EXTEN | G37: =I37&"ไม่มีการกำหนดค่าที่ DB ONLSTD TBL WS_CLIENT_RETURN_LEN_EXTEN" -> ไม่มีไม่มีการกำหนดค่าที่ DB ONLSTD TBL WS_CLIENT_RETURN_LEN_EXTEN | H37: Pass | I37: ไม่มี
A38: =IF((C38)="","",MAX($A$2:A37)+1) -> 18 | B38: =IF((C38)="","",$D$9) -> 244236 | C38: P1 | D38: ตรวจสอบการกำหนดค่า URL Check Digit / Check Length ที่ DB ONLSTD TBL WS_CLIENT_REF | F38: มีการกำหนดค่าที่ DB ONLSTD TBL WS_CLIENT_REF | G38: =I38&"การกำหนดค่าที่ DB ONLSTD TBL WS_CLIENT_REF" -> ไม่มีการกำหนดค่าที่ DB ONLSTD TBL WS_CLIENT_REF | H38: Pass | I38: ไม่มี
A39: =IF((C39)="","",MAX($A$2:A38)+1) -> 19 | B39: =IF((C39)="","",$D$9) -> 244236 | C39: P1 | D39: ตรวจสอบการกำหนดค่า URL Check Digit / Check Length ที่ DB ONLSTD TBL WS_CLIENT_LEN_EXTEN | F39: ไม่มีการกำหนดค่าที่ DB ONLSTD TBL WS_CLIENT_LEN_EXTEN | G39: =I39&"การกำหนดค่าที่ DB ONLSTD TBL WS_CLIENT_LEN_EXTEN" -> ไม่มีการกำหนดค่าที่ DB ONLSTD TBL WS_CLIENT_LEN_EXTEN | H39: Pass | I39: ไม่มี
A40: =IF((C40)="","",MAX($A$2:A39)+1) -> 20 | B40: =IF((C40)="","",$D$9) -> 244236 | C40: P1 | D40: ตรวจสอบการกำหนดค่า PREFIX ที่ DB ONLSTD TBL WS_CLIENT_PREFIX | F40: มีการกำหนดค่าที่ DB ONLSTD TBL WS_CLIENT_PREFIX | G40: =I40&"การกำหนดค่าที่ DB ONLSTD TBL WS_CLIENT_PREFIX " -> มีการกำหนดค่าที่ DB ONLSTD TBL WS_CLIENT_PREFIX | H40: Pass | I40: มี
A41: =IF((C41)="","",MAX($A$2:A40)+1) -> 21 | B41: =IF((C41)="","",$D$9) -> 244236 | C41: P1 | D41: ตรวจสอบ "ลิ้งเครื่องPOS ที่ใช้ในการทดสอบ" ที่ DB ONLSTD TBL = WS_CLIENT_GRP | F41: อ้างอิง ROW ที่ VENDOR_ID = Tax_ID ของผวจ.ดังกล่าว SERVICE_ID = รหัส Service ของผวจ.ดังกล่าว - ที่ Field "POS_URL = http://XX.XXX.XXX.XX:XX/DCWSCDSONLINE/WSCDSService" | G41: อ้างอิง ROW ที่ VENDOR_ID = Tax_ID ของผวจ.ดังกล่าว SERVICE_ID = รหัส Service ของผวจ.ดังกล่าว - ที่ Field "POS_URL = http://XX.XXX.XXX.XX:XX/DCWSCDSONLINE/WSCDSService" | H41: Pass
...

Sheet CONFIG
A1: ONLSTD.WS_CLIENT_CONFIG
A3: VENDOR_ID | B3: SERVICE_ID | C3: LOG_ID | D3: DB_ID | E3: TX_TABLE | F3: LOG_TABLE | G3: SYSTEM_TYPE | H3: MIN_AMT | I3: MAX_AMT | J3: OR_TIMEOUT | K3: EFF_DATE | L3: EXPIRE_DATE | M3: EFF_TIME | N3: EXPIRE_TIME | O3: CREATE_DATE | P3: LAST_UPDATE_DATE | Q3: AUSER_ID | R3: TX_ID_TABLE | S3: LOG_ID_TABLE | T3: VENDOR_CODE | U3: VENDOR_NAME | V3: DX_READ_TBL | W3: CHK_AMT_SRV | X3: CHK_AMT_FNT | Y3: CALC_VAT | Z3: CHK_AMT_BEFORE | AA3: CHK_AMT_AFTER | AB3: FULL_FORM_TYPE | AC3: USERID | AD3: PASSWD | AE3: SERVICE_CHARGE | AF3: SRV_OPEN_TIME | AG3: SRV_CLOSE_TIME | AH3: CHK_OR_OVERDAY | AI3: CHK_FULL_SET | AJ3: PARTIAL_AMT | AK3: CALL_SRV_TIMEOUT | AL3: SHORT_VENDOR_NAME | AM3: CHK_OR_OVERLIMIT | AN3: CHK_RETURN_TX | AO3: CHK_PRINT_SLIP | AP3: DISCOUNT_CHARGE | AQ3: CHK_REF_MATCH | AR3: AIRLINE | AS3: CALL_VENDOR_TIMEOUT | AT3: SWITCH_OFFLINE | AU3: SRV_OPEN_TIME_OVER_DAY | AV3: CHK_DUP_AFTER | AW3: SR_RUNNING_FORMAT | AX3: CHK_SPECIAL_REF | AY3: TAX_FULLFORM | AZ3: CHK_RETURN_SERVICE | BA3: CHK_PRODUCT_REF | BB3: OR_HHMM | BC3: POPUP | BD3: FULL_FORM_OR_TYPE | BE3: FULL_FORM_OR_CONFIRM_TYPE | BF3: CONFIRM_TYPE | BG3: VENDOR_USERID | BH3: INQUIRY_PROD_CODE | BI3: INQUIRY_CLIENT | BJ3: INQUIRY_SERVICE | BK3: XCODE | BL3: SAMEDAY_TEXT_NAME_ID | BM3: VENDOR_PASSWD | BN3: INCOMPLETE_STATUS | BO3: FLAG_IS_OPEN | BP3: CASH_OUT_FLAG | BQ3: CHK_BRANCH_IS_ALLOWED | BR3: FLAG_STD_CASHOUT_CALLSRV | BS3: FLAG_STD_OFFSET_CALLSRV | BT3: GET_VAT_VENDOR | BU3: GET_AMOUNT_VENDOR | BV3: MODIFY_PRINTSLIP_POP_INFO | BW3: CASH_REPORT_FLAG | BX3: MIN_AMT_PER_BILL | BY3: MAX_AMT_PER_BILL | BZ3: DISPLAY_BILL | CA3: CHK_UPDATE_SERVICE | CB3: CHK_AMT_METHOD | CC3: SERVICE_CHARGE_METHOD | CD3: SEND_SMS_CONFRIM | CE3: USE_BARCODE | CF3: CONFIG_OPENSERVICE | CG3: OPEN_CONFIRM_ALLDAY | CH3: OR_NOT_ALLOW_AFTER_TIME | CI3: INSERT_PRINTSLIP_METHOD | CJ3: CHK_UPDATE_CUS_TEL_NO | CK3: REWARD_TYPE | CL3: OFFLINE_SYSTEM_TYPE | CM3: PROMOTION_PROCESS_STATUS | CN3: PROMOTION_PROCESS_DATE | CO3: CHK_UPDATE_VENDOR | CP3: PARTIAL_VAT | CQ3: CHK_COUPON
A4: 0994000160151 | B4: 07 | C4: BKK | D4: WS_STDDB | E4: WS_ONLINE_TX | F4: WS_ONLINE_LOG | G4: FF | H4: 1 | I4: 90000 | J4: 10800 | K4: 45862 | L4: 401570 | M4: 00:00:00 | N4: 00:00:00 | O4: 45824 | P4: 45824 | Q4: PARINDA | R4: TXID_NEXT_SEQ | S4: LOGID_NEXT_SEQ | T4: 10972 | U4: BKK | V4: N | W4: N | X4: 1 | Y4: N | Z4: N | AA4: Y | AB4: H | AE4: 2 | AH4: Y | AI4: N | AJ4: N | AK4: 15 | AL4: BKK | AN4: N | AO4: Y | AP4: N | AQ4: N | AR4: N | AS4: 3 | AT4: Y | AU4: N | AV4: N | AW4: STD | AX4: N | AY4: N | AZ4: N | BA4: N | BB4: 20:05 | BO4: A | BT4: N | BU4: N | BV4: N | BZ4: N | CA4: N | CE4: N | CF4: Y | CG4: N | CJ4: N | CM4: Y | CN4: 42668.508 | CO4: N
A7: ONLSTD.WS_CLIENT_CHARGE
A9: ❌ No Data
A12: ONLSTD.WS_CLIENT_CHARGE_STEP
A14: VENDOR_ID | B14: SERVICE_ID | C14: MIN_AMOUNT | D14: MAX_AMOUNT | E14: SERVICE_CHARGE_CENTRE | F14: SERVICE_CHARGE_PROVINCES | G14: EFF_DATE | H14: EXPIRE_DATE | I14: EFF_TIME | J14: EXPIRE_TIME | K14: CREATE_DATE | L14: LAST_UPDATE_DATE | M14: AUSER_ID
A15: 0994000160151 | B15: 07 | C15: 1 | D15: 49000.00 | E15: 10 | F15: 10 | G15: 45882 | H15: 401598 | I15: 00:00:00 | J15: 00:00:00 | K15: 45882 | L15: 45882 | M15: PARINDA
A16: 0994000160151 | B16: 07 | C16: 49000.25 | D16: 90000.00 | E16: 20 | F16: 20 | G16: 45882 | H16: 401598 | I16: 00:00:00 | J16: 00:00:00 | K16: 45882 | L16: 45882 | M16: PARINDA
A19: ONLSTD.WS_CLIENT_AUTOFIXTX
A21: SERVICE_ID | B21: VENDOR_ID | C21: VENDOR_CODE | D21: VENDOR_NAME | E21: DB_ID | F21: TX_TABLE | G21: TX_ID_TABLE | H21: AUTOFIX_INTERVAL | I21: SERVER_RUN | J21: MAIL_LIMIT | K21: RESEND_BF2_TIME | L21: AUTO_MAKECOMPLETE | M21: RESEND_BF2_INTERVAL | N21: CHECK_ONPROCESS | O21: F1PRIORITY | P21: SEND_MAIL | Q21: CHECK_RETURN_REF | R21: SEND_MAIL_PREVIOUS_HOUR
A22: 07 | B22: 0994000160151 | C22: 10972 | D22: BKK | E22: WS_STDDB | F22: WS_ONLINE_TX | G22: TXID_NEXT_SEQ | H22: 360 | I22: Test5Job1 | J22: 0 | K22: 3 | L22: Y | M22: 60 | N22: Y | O22: 63 | P22: N
A25: ONLSTD.WS_CLIENT_AUTOFIXTX_CANCEL
A27: ❌ No Data
A30: ONLSTD.WS_STD_SERVICE_LOOKUP
A32: LOOKUP_ID | B32: SERVICE_NAME | C32: WS_INF_ADDRESS | D32: SERVICE_ADDRESS | E32: VENDOR_ID | F32: SERV_ID | G32: SERVER_NAME
A33: 1097202 | B33: DataExchange | C33: http://10.151.36.192:8080/COU_DCVENDORONLINE_1H_BKK/BKKCallVendorPort | D33: https://bkkwastepayapp-staging.bangkok.go.th/api/CounterServiceExchange | E33: 0994000160151 | F33: 07 | G33: JVM
A34: 1097202 | B34: DataExchangeCancel | C34: http://10.151.36.192:8080/COU_DCVENDORONLINE_1H_BKK/BKKCallVendorPort | E34: 0994000160151 | F34: 07 | G34: JVM
A35: 1097202 | B35: DataExchangeConfirm | C35: http://10.151.36.192:8080/COU_DCVENDORONLINE_1H_BKK/BKKCallVendorPort | D35: https://bkkwastepayapp-staging.bangkok.go.th/api/CounterServiceExchange | E35: 0994000160151 | F35: 07 | G35: JVM
A36: 1097202 | B36: OR | C36: http://10.151.36.192:8080/COU_DCVENDORONLINE_1H_BKK/BKKCallVendorPort | D36: https://bkkwastepayapp-staging.bangkok.go.th/api/CounterServiceExchange | E36: 0994000160151 | F36: 07 | G36: JVM
A37: 1097202 | B37: ORCancel | C37: http://10.151.36.192:8080/COU_DCVENDORONLINE_1H_BKK/BKKCallVendorPort | E37: 0994000160151 | F37: 07 | G37: JVM
A38: 1097202 | B38: ORConfirm | C38: http://10.151.36.192:8080/COU_DCVENDORONLINE_1H_BKK/BKKCallVendorPort | D38: https://bkkwastepayapp-staging.bangkok.go.th/api/CounterServiceExchange | E38: 0994000160151 | F38: 07 | G38: JVM
A41: ONLSTD.WS_STD_ERROR_CODE
A43: ERROR_ID | B43: DESC_THAI | C43: DESC_ENG | D43: CLIENT_CODE
A44: 91097202001 | B44: ไม่พบ ref1 หรือ ref2 ที่ตรงกัน | C44: Reference code is notfound | D44: 10972
A45: 91097202002 | B45: Order นี้มีการชำระเงินแล้ว | C45: Already paid | D45: 10972
A46: 91097202004 | B46: ยอดชำระเงิน ไม่ตรงกับที่กำหนดไว้ | C46: Not match received_x000D_ amount | D46: 10972
A47: 91097202099 | B47: เกิดปัญหาที่ระบบ ไม่สามารถรับชำระได้ | C47: System Error | D47: 10972
A50: ONLSTD.WS_CLIENT_REPRINT
A52: ❌ No Data
A55: ONLSTD.WS_CLIENT_REF
A57: VENDOR_ID | B57: SERVICE_ID | C57: REFERENCE_SEQ | D57: CHK_LEN | E57: CHK_LEN_EXTEN | F57: CHK_DUP | G57: CHK_PREFIX | H57: EFF_DATE | I57: EXPIRE_DATE | J57: EFF_TIME | K57: EXPIRE_TIME | L57: CREATE_DATE | M57: LAST_UPDATE_DATE | N57: AUSER_ID | O57: CHK_DIGIT_INTERNAL | P57: CHK_DIGIT_EXTERNAL | Q57: CHK_LIMIT_CASHOUT_DUP | R57: CHK_COUNT_LIMIT_CASHOUT
A58: 0994000160151 | B58: 07 | C58: 1 | D58: 18 | E58: N | F58: Y | G58: N | H58: 45894.648 | I58: 401676 | J58: 00:00:00 | K58: 00:00:00 | L58: 45894.648 | M58: 45894.648 | R58: 0
A59: 0994000160151 | B59: 07 | C59: 2 | D59: 18 | E59: N | F59: Y | G59: N | H59: 45894.648 | I59: 401676 | J59: 00:00:00 | K59: 00:00:00 | L59: 45894.648 | M59: 45894.648 | R59: 0
A60: 0994000160151 | B60: 07 | C60: 3 | D60: 10 | E60: N | F60: N | G60: N | H60: 45894.648 | I60: 401676 | J60: 00:00:00 | K60: 00:00:00 | L60: 45894.648 | M60: 45894.648 | R60: 0
A63: ONLSTD.WS_CLIENT_RETURN
A65: ❌ No Data
A68: ONLSTD.WS_CLIENT_LEN_EXTEN
A70: ❌ No Data
A73: ONLSTD.WS_CLIENT_PREFIX
...

Sheet Validation
B2: No. | C2: GROUP | D2: Case | H2: Datatest | K2: Result | Q2: Status | R2: Remark
B3: 1 | C3: Flow | D3: ทำรายการ DataExchange | K3: true / 100 / success
B4: 2 | D4: ทำรายการ Cancel ด้วย DataExchange | K4: true / 100 / success
B5: 3 | D5: ทำรายการ DataExchange ด้วย DataExchange Cancel | K5: true / 100 / success
B6: 4 | D6: ทำรายการ DataExchangeConfirm | K6: true / 100 / success
B7: 6 | D7: ทำรายการ Or | K7: true / 100 / success
B8: 7 | D8: ทำรายการ OrCancel | K8: true / 100 / success
B9: 8 | D9: ทำรายการ OR ด้วยรายการ ORCancel | K9: true / 100 / success
B10: 9 | D10: ทำรายการ ORConfirm | K10: true / 100 / success
B11: 12 | D11: ทำรายการ Exchange ด้วย ORConfirm | K11: true / 100 / success
B12: 18 | D12: ทำรายการ Reprint (ภายในเวลาที่กำหนด) และมากกว่า 1 ครั้ง | K12: false / 208 / ผู้ว่าจ้างนี้ไม่อนุญาตให้ Reprint
B13: 19 | C13: Validation | D13: ทำรายการ DataExchange Ref 1 ความยาวมากกว่า 18 หลัก | K13: false / 123 / ความยาวข้อมูลไม่ถูกต้อง
B14: 20 | D14: ทำรายการ DataExchange Ref 1 ความยาวน้อยกว่า 18 หลัก | K14: false / 123 / ความยาวข้อมูลไม่ถูกต้อง
B15: 21 | D15: ทำรายการ DataExchange Ref 1 ความยาวเท่ากับ 18 หลัก | K15: true / 100 / success
B16: 22 | D16: ทำรายการ DataExchange Ref 1 ความยาว null หลัก | K16: false / 123 / ความยาวข้อมูลไม่ถูกต้อง
B17: 23 | D17: ทำรายการ DataExchange Ref 2 ความยาวมากกว่า 18 หลัก | K17: false / 123 / ความยาวข้อมูลไม่ถูกต้อง
B18: 24 | D18: ทำรายการ DataExchange Ref 2 ความยาวน้อยกว่า 18 หลัก | K18: false / 123 / ความยาวข้อมูลไม่ถูกต้อง
B19: 25 | D19: ทำรายการ DataExchange Ref 2 ความยาวเท่ากับ 18 หลัก | K19: true / 100 / success
B20: 26 | D20: ทำรายการ DataExchange Ref 2 ความยาว null 18 หลัก | K20: false / 123 / ความยาวข้อมูลไม่ถูกต้อง
B21: 23 | D21: ทำรายการ DataExchange Ref 3 ความยาวมากกว่า 10 หลัก | K21: false / 123 / ความยาวข้อมูลไม่ถูกต้อง
B22: 24 | D22: ทำรายการ DataExchange Ref 3 ความยาวน้อยกว่า 10 หลัก | K22: false / 123 / ความยาวข้อมูลไม่ถูกต้อง
B23: 25 | D23: ทำรายการ DataExchange Ref 3 ความยาวเท่ากับ 10 หลัก | K23: true / 100 / success
B24: 26 | D24: ทำรายการ DataExchange Ref 3 ความยาว null หลัก | K24: false / 123 / ความยาวข้อมูลไม่ถูกต้อง
B25: 27 | D25: ยอดเงินเป็นค่า Null | K25: false / 119 / ขออภัยปิดปรับปรุง 30 นาที
B26: 28 | D26: ยอดเงิน Min 1 | R26: ไม่มี Dataทดสอบ
B27: 29 | D27: ยอดเงิน Max 90000 | R27: ไม่มี Dataทดสอบ
B28: 30 | D28: ยอดเงินต่ำกว่า min 0 | K28: false / 124 / รับชำระจำนวนเงินขั้นต่ำ 1.00 บาท | R28: 0 บาท
B29: 31 | D29: ยอดเงินมากกว่า max 90001 | K29: false / 125 / รับชำระไม่เกิน 90,000.00 บาท | R29: 1000000 บาท
B30: 32 | D30: ยอดเงินเป็นทศนิยมลงตัว 500.25 | K30: true / 100 / success
B31: 33 | D31: ยอดเงินเป็นทศนิยมไม่ลงตัว 500.24 | R31: ไม่มี Dataทดสอบ
B32: 34 | C32: Fee | D32: ตรวจสอบ ZONE 1 ขั้น1 | K32: true / 100 / success
B33: 35 | D33: ตรวจสอบ ZONE 1 ขั้น2 | K33: true / 100 / success
B34: 36 | D34: ตรวจสอบ ZONE 2 ขั้น1 | K34: true / 100 / success
B35: 37 | D35: ตรวจสอบ ZONE 2 ขั้น2 | K35: true / 100 / success
B36: 38 | C36: Duplicate | D36: Duplicate Status 1 | K36: true / 131 / การรับชำระไม่สมบูรณ์ โดยร้านสาขา X /เครื่อง Y
B37: 39 | D37: Duplicate Status 2 | K37: true / 131 / การรับชำระไม่สมบูรณ์ โดยร้านสาขา X /เครื่อง Y
B38: 40 | D38: Duplicate Status 3 | K38: true / 311 / มีการรับชำระรายการนี้อยู่แล้ว ในฐานข้อมูล โดยร้านสาขา X /เครื่อง Y
B39: 41 | D39: Duplicate Status 4
B40: 42 | D40: Duplicate Status 5 | K40: true / 100 / success
B41: 43 | D41: Duplicate Status 6 | K41: true / 311 / มีการรับชำระรายการนี้อยู่แล้ว ในฐานข้อมูล โดยร้านสาขา X /เครื่อง Y
...

Sheet Autofix
A2: AutoFix_Cancel กรณีที่รายการรับชำระค้าง Status 1 (BF1) ที่ระบบ Online และไม่มีรายการดังกล่าวที่ POS ทำรายการ Status = 1 ค้างที่ online
A4: ก่อนซ่อมรายการ
A5: DB : WS_ONLINE_TX
A6: TX_ID | B6: CLIENT_CODE | C6: SERVICE_CODE | D6: COUNTER_NO | E6: TERM_NO | F6: POS_TAX_ID | G6: SERVICE_RUN_NO | H6: RECORD_STATUS | I6: OPERATING_DATE_TIME | J6: CLIENT_SERVICE_NO | K6: CLIENT_SERVICE_RUNNO | L6: VAT_RATE | M6: AMOUNT_RECEIVED | N6: VAT_AMOUNT | O6: BILL_TYPE | P6: BILL_NO | Q6: CUSTOMER_NAME | R6: CUSTOMER_ADDR_1 | S6: CUSTOMER_ADDR_2 | T6: CUSTOMER_ADDR_3 | U6: CUSTOMER_TEL_NO | V6: REFERENCE_1 | W6: REFERENCE_2 | X6: REFERENCE_3 | Y6: REFERENCE_4 | Z6: REFERENCE_5 | AA6: REFERENCE_6 | AB6: REFERENCE_7 | AC6: COMM_PAID_CODE | AD6: ZONE | AE6: R_SERVICE_RUNNO | AF6: CANCEL_OPERATING | AG6: OPERATE_BY_STAFF | AH6: OPERATING_ROUND | AI6: TEL_CODE | AJ6: FILLER | AK6: TRX_TYPE | AL6: STATUS | AM6: SYSTEM_DATE_TIME | AN6: RETRY_COUNT | AO6: SENDMAIL_COUNT | AP6: PAYMENT_CHANNEL | AQ6: TRANSACTION_ID | AR6: CLIENT_CODE_FR | AS6: SERVICE_CODE_FR | AT6: RETRY_COUNT_CANCEL | AU6: TIMEOUT_COUNT_CANCEL | AV6: AMOUNT_RECEIVED_VENDOR | AW6: VAT_AMOUNT_VENDOR | AX6: POS_SYSTEM_DATE_TIME | AY6: REFERENCE_9 | AZ6: CANCEL_ID | BA6: RETURN1 | BB6: RETURN2 | BC6: RETURN3 | BD6: COUPON_STATUS | BE6: CUSTOMER_TAX_ID | BF6: CUSTOMER_BRANCH_CODE | BG6: CUSTOMER_RECEIPT_NAME | BH6: CUSTOMER_RECEIPT_ADDR | BI6: OFFLINE_TXN | BJ6: ITOUCH_COUNTER_NO | BK6: ITOUCH_TERM_NO | BL6: ITOUCH_PAYMENT_CHANNEL
A8: 14026271 | B8: 087 | C8: 01 | D8: 01322 | E8: 1 | H8: A | I8: 9/9/2020 10:07:31 | J8: 01 | L8: 7.0 | M8: 2000 | N8: 0 | O8: B | V8: 5100110108640 | W8: กก0001 | X8: NOBILL | Y8: REALTIME | AD8: 1 | AG8: 2 | AH8: 3 | AK8: N | AL8: 1 | AM8: 9/9/2020 11:24:49 | AN8: 8 | AP8: C05 | AU8: 0 | AX8: 9/9/2020 10:07:31
A9: 14026272 | B9: CS | C9: S | D9: 01322 | E9: 1 | H9: A | I9: 9/9/2020 10:07:31 | J9: CS | L9: 7.0 | M9: 15.00 | N9: 0 | O9: B | V9: 3011106624 | W9: 01 | X9: 14026271 | AD9: 1 | AG9: 2 | AH9: 3 | AK9: N | AL9: 0 | AM9: 9/9/2020 11:24:49 | AN9: 8 | AP9: C05 | AU9: 0 | AX9: 9/9/2020 10:07:31
A12: หลังซ่อมรายการ
A13: DB : WS_ONLINE_TX
A14: TX_ID | B14: CLIENT_CODE | C14: SERVICE_CODE | D14: COUNTER_NO | E14: TERM_NO | F14: POS_TAX_ID | G14: SERVICE_RUN_NO | H14: RECORD_STATUS | I14: OPERATING_DATE_TIME | J14: CLIENT_SERVICE_NO | K14: CLIENT_SERVICE_RUNNO | L14: VAT_RATE | M14: AMOUNT_RECEIVED | N14: VAT_AMOUNT | O14: BILL_TYPE | P14: BILL_NO | Q14: CUSTOMER_NAME | R14: CUSTOMER_ADDR_1 | S14: CUSTOMER_ADDR_2 | T14: CUSTOMER_ADDR_3 | U14: CUSTOMER_TEL_NO | V14: REFERENCE_1 | W14: REFERENCE_2 | X14: REFERENCE_3 | Y14: REFERENCE_4 | Z14: REFERENCE_5 | AA14: REFERENCE_6 | AB14: REFERENCE_7 | AC14: COMM_PAID_CODE | AD14: ZONE | AE14: R_SERVICE_RUNNO | AF14: CANCEL_OPERATING | AG14: OPERATE_BY_STAFF | AH14: OPERATING_ROUND | AI14: TEL_CODE | AJ14: FILLER | AK14: TRX_TYPE | AL14: STATUS | AM14: SYSTEM_DATE_TIME | AN14: RETRY_COUNT | AO14: SENDMAIL_COUNT | AP14: PAYMENT_CHANNEL | AQ14: TRANSACTION_ID | AR14: CLIENT_CODE_FR | AS14: SERVICE_CODE_FR | AT14: RETRY_COUNT_CANCEL | AU14: TIMEOUT_COUNT_CANCEL | AV14: AMOUNT_RECEIVED_VENDOR | AW14: VAT_AMOUNT_VENDOR | AX14: POS_SYSTEM_DATE_TIME | AY14: REFERENCE_9 | AZ14: CANCEL_ID | BA14: RETURN1 | BB14: RETURN2 | BC14: RETURN3 | BD14: COUPON_STATUS | BE14: CUSTOMER_TAX_ID | BF14: CUSTOMER_BRANCH_CODE | BG14: CUSTOMER_RECEIPT_NAME | BH14: CUSTOMER_RECEIPT_ADDR | BI14: OFFLINE_TXN | BJ14: ITOUCH_COUNTER_NO | BK14: ITOUCH_TERM_NO | BL14: ITOUCH_PAYMENT_CHANNEL
A16: 14026271 | B16: 087 | C16: 01 | D16: 01322 | E16: 1 | H16: A | I16: 9/9/2020 10:07:31 | J16: 01 | L16: 7.0 | M16: 2000 | N16: 0 | O16: B | V16: 5100110108640 | W16: กก0001 | X16: NOBILL | Y16: REALTIME | AD16: 1 | AG16: BF1ONLSTD | AH16: 3 | AK16: N | AL16: 5 | AM16: 9/9/2020 11:29:10 | AN16: 8 | AP16: C05 | AU16: 0 | AX16: 9/9/2020 10:07:31
A17: 14026272 | B17: CS | C17: S | D17: 01322 | E17: 1 | H17: A | I17: 9/9/2020 10:07:31 | J17: CS | L17: 7.0 | M17: 15.00 | N17: 0 | O17: B | V17: 3011106624 | W17: 01 | X17: 14026271 | AD17: 1 | AG17: 2 | AH17: 3 | AK17: N | AL17: 0 | AM17: 9/9/2020 11:24:49 | AN17: 8 | AP17: C05 | AU17: 0 | AX17: 9/9/2020 10:07:31
A20: DB : WS_ONLINE_LOG
A21: LOG_ID | B21: CLIENT_CODE | C21: SERVICE_CODE | D21: TX_ID | E21: EVENT | F21: SUCCESS | G21: CODE | H21: BUSINESS_DATE | I21: BUSINESS_TIME | J21: SYSTEM_DATE | K21: SYSTEM_TIME | L21: USER_ID | M21: STATUS | N21: DB_IP_POS | O21: EVENT_STEP | P21: HQ_SERVER | Q21: POS_SYSTEM_DATE | R21: POS_SYSTEM_TIME | S21: LOG_FILE_ID
A23: 53809781 | B23: 087 | C23: 00 | D23: 14026271 | E23: GEODataExchange | F23: true | G23: 100 | H23: 2020/09/09 | I23: 10:07:31 | J23: 09/09/2020 | K23: 11:24:49 | L23: 2 | M23: 1 | P23: 10.182.247.103 | Q23: 2020/09/09 | R23: 10:07:31 | S23: csonlapqa02.30680046
A24: 53809782 | B24: CS | C24: S | D24: 14026272 | E24: GEODataExchange | F24: true | G24: 100 | H24: 2020/09/09 | I24: 10:07:31 | J24: 09/09/2020 | K24: 11:24:49 | L24: 2 | M24: 1 | P24: 10.182.247.103 | Q24: 2020/09/09 | R24: 10:07:31 | S24: csonlapqa02.30680046
A25: 53809829 | B25: 087 | C25: 01 | D25: 14026271 | E25: GEODataExchangeCancel | F25: true | G25: 100 | H25: 2020/09/09 | I25: 10:07:31 | J25: 09/09/2020 | K25: 11:29:10 | L25: BF1ONLSTD | M25: 5 | N25: 117.113.122.111 | P25: 10.182.247.103 | S25: csonlapqa02.30680084
A28: AutoFix_Confirm กรณีที่รายการรับชำระค้าง Status 1 (BF1) ที่ระบบ Online และมีรายการดังกล่าวที่ POS ทำรายการ Status = 3 ปรับเป็น 1
B30: วิธีการทดสอบ (กรณียังไม่มีโปรแกรมที่หน้าร้าน)
B31: 1. ทำรายการที่เครื่อง POS 1 รายการ ได้ใบเสร็จ ( Status = 3 )
B32: 2. ทำรายการที่ SIMU 1 รายการ Confirm ( Status = 3 )
B33: 3. รายการที่ POS ให้แก้ (TX.ID ,Client_ID,ข้อมูลรับชำระ เช่น ref1. , ref2. ,billAmount ให้เป็นรายการเหมือนที่ SIMU ) ที่ Table DB TC_DETAIL ,TC_ONLINE_PROCESS ให้ตรงกับรายการที่ SIMU
B34: 4. รายการที่ SIMU ให้แก้ COUNTER_NO ให้ตรงกับที่ POS และลบ Column SERVICE_RUN_NO และ Column CLIENT_SERVICE_RUN_NO ที่ Table DB WS_ONLINE_TX
B35: 5. แก้ Status ที่ Online
A37: ก่อนซ่อมรายการ
A38: DB : WS_ONLINE_TX
A39: TX_ID | B39: CLIENT_CODE | C39: SERVICE_CODE | D39: COUNTER_NO | E39: TERM_NO | F39: POS_TAX_ID | G39: SERVICE_RUN_NO | H39: RECORD_STATUS | I39: OPERATING_DATE_TIME | J39: CLIENT_SERVICE_NO | K39: CLIENT_SERVICE_RUNNO | L39: VAT_RATE | M39: AMOUNT_RECEIVED | N39: VAT_AMOUNT | O39: BILL_TYPE | P39: BILL_NO | Q39: CUSTOMER_NAME | R39: CUSTOMER_ADDR_1 | S39: CUSTOMER_ADDR_2 | T39: CUSTOMER_ADDR_3 | U39: CUSTOMER_TEL_NO | V39: REFERENCE_1 | W39: REFERENCE_2 | X39: REFERENCE_3 | Y39: REFERENCE_4 | Z39: REFERENCE_5 | AA39: REFERENCE_6 | AB39: REFERENCE_7 | AC39: COMM_PAID_CODE | AD39: ZONE | AE39: R_SERVICE_RUNNO | AF39: CANCEL_OPERATING | AG39: OPERATE_BY_STAFF | AH39: OPERATING_ROUND | AI39: TEL_CODE | AJ39: FILLER | AK39: TRX_TYPE | AL39: STATUS | AM39: SYSTEM_DATE_TIME | AN39: RETRY_COUNT | AO39: SENDMAIL_COUNT | AP39: PAYMENT_CHANNEL | AQ39: TRANSACTION_ID | AR39: CLIENT_CODE_FR | AS39: SERVICE_CODE_FR | AT39: RETRY_COUNT_CANCEL | AU39: TIMEOUT_COUNT_CANCEL | AV39: AMOUNT_RECEIVED_VENDOR | AW39: VAT_AMOUNT_VENDOR | AX39: POS_SYSTEM_DATE_TIME | AY39: REFERENCE_9 | AZ39: CANCEL_ID | BA39: RETURN1 | BB39: RETURN2 | BC39: RETURN3 | BD39: COUPON_STATUS | BE39: CUSTOMER_TAX_ID | BF39: CUSTOMER_BRANCH_CODE | BG39: CUSTOMER_RECEIPT_NAME | BH39: CUSTOMER_RECEIPT_ADDR | BI39: OFFLINE_TXN | BJ39: ITOUCH_COUNTER_NO | BK39: ITOUCH_TERM_NO | BL39: ITOUCH_PAYMENT_CHANNEL
A41: 14026295 | B41: 087 | C41: 01 | D41: 11104 | E41: 1 | F41: 1110412345678 | H41: A | I41: 14/9/2020 2:22:52 | J41: 01 | L41: 7.0 | M41: 100 | N41: 6.54 | O41: E | P41: 1 | V41: 5100110108640 | W41: 0718352277370 | X41: NOBILL | Y41: REALTIME | AD41: 1 | AG41: 0555502 | AH41: 1 | AK41: N | AL41: 1 | AM41: 9/9/2020 11:57:48 | AN41: 8 | AP41: C05 | AU41: 0 | AX41: 14/9/2020 2:22:52
A42: 14026296 | B42: CS | C42: S | D42: 11104 | E42: 1 | F42: 1110412345678 | G42: 000029 | H42: A | I42: 14/9/2020 2:22:52 | J42: CS | K42: 000009 | L42: 7.0 | M42: 15 | N42: 0.98 | O42: B | P42: 9 | V42: 3011106624 | W42: 01 | X42: 14026295 | AD42: 1 | AG42: 0555502 | AH42: 1 | AK42: N | AL42: 3 | AM42: 9/9/2020 11:57:48 | AN42: 8 | AP42: C05 | AU42: 0 | AX42: 14/9/2020 2:22:52
A44: หลังซ่อมรายการ
A45: DB : WS_ONLINE_TX
A46: TX_ID | B46: CLIENT_CODE | C46: SERVICE_CODE | D46: COUNTER_NO | E46: TERM_NO | F46: POS_TAX_ID | G46: SERVICE_RUN_NO | H46: RECORD_STATUS | I46: OPERATING_DATE_TIME | J46: CLIENT_SERVICE_NO | K46: CLIENT_SERVICE_RUNNO | L46: VAT_RATE | M46: AMOUNT_RECEIVED | N46: VAT_AMOUNT | O46: BILL_TYPE | P46: BILL_NO | Q46: CUSTOMER_NAME | R46: CUSTOMER_ADDR_1 | S46: CUSTOMER_ADDR_2 | T46: CUSTOMER_ADDR_3 | U46: CUSTOMER_TEL_NO | V46: REFERENCE_1 | W46: REFERENCE_2 | X46: REFERENCE_3 | Y46: REFERENCE_4 | Z46: REFERENCE_5 | AA46: REFERENCE_6 | AB46: REFERENCE_7 | AC46: COMM_PAID_CODE | AD46: ZONE | AE46: R_SERVICE_RUNNO | AF46: CANCEL_OPERATING | AG46: OPERATE_BY_STAFF | AH46: OPERATING_ROUND | AI46: TEL_CODE | AJ46: FILLER | AK46: TRX_TYPE | AL46: STATUS | AM46: SYSTEM_DATE_TIME | AN46: RETRY_COUNT | AO46: SENDMAIL_COUNT | AP46: PAYMENT_CHANNEL | AQ46: TRANSACTION_ID | AR46: CLIENT_CODE_FR | AS46: SERVICE_CODE_FR | AT46: RETRY_COUNT_CANCEL | AU46: TIMEOUT_COUNT_CANCEL | AV46: AMOUNT_RECEIVED_VENDOR | AW46: VAT_AMOUNT_VENDOR | AX46: POS_SYSTEM_DATE_TIME | AY46: REFERENCE_9 | AZ46: CANCEL_ID | BA46: RETURN1 | BB46: RETURN2 | BC46: RETURN3 | BD46: COUPON_STATUS | BE46: CUSTOMER_TAX_ID | BF46: CUSTOMER_BRANCH_CODE | BG46: CUSTOMER_RECEIPT_NAME | BH46: CUSTOMER_RECEIPT_ADDR | BI46: OFFLINE_TXN | BJ46: ITOUCH_COUNTER_NO | BK46: ITOUCH_TERM_NO | BL46: ITOUCH_PAYMENT_CHANNEL
A48: 14026295 | B48: 087 | C48: 01 | D48: 11104 | E48: 1 | F48: 1110412345678 | G48: 000028 | H48: A | I48: 14/9/2020 2:22:52 | J48: 01 | K48: 000001 | L48: 7.0 | M48: 100.00 | N48: 6.54 | O48: E | P48: 1 | V48: 5100110108640 | W48: 0718352277370 | X48: NOBILL | Y48: REALTIME | AD48: 1 | AG48: BF1ONLSTD | AH48: 1 | AK48: N | AL48: 3 | AM48: 9/9/2020 13:35:28 | AN48: 8 | AP48: C05 | AU48: 0 | AX48: 14/9/2020 2:22:52
A49: 14026296 | B49: CS | C49: S | D49: 11104 | E49: 1 | F49: 1110412345678 | G49: 000029 | H49: A | I49: 14/9/2020 2:22:52 | J49: CS | K49: 000009 | L49: 7.0 | M49: 15 | N49: 0.98 | O49: B | P49: 9 | V49: 3011106624 | W49: 01 | X49: 14026295 | AD49: 1 | AG49: 0555502 | AH49: 1 | AK49: N | AL49: 3 | AM49: 9/9/2020 11:57:48 | AN49: 8 | AP49: C05 | AU49: 0 | AX49: 14/9/2020 2:22:52
A52: DB : WS_ONLINE_LOG
A53: LOG_ID | B53: CLIENT_CODE | C53: SERVICE_CODE | D53: TX_ID | E53: EVENT | F53: SUCCESS | G53: CODE | H53: BUSINESS_DATE | I53: BUSINESS_TIME | J53: SYSTEM_DATE | K53: SYSTEM_TIME | L53: USER_ID | M53: STATUS | N53: DB_IP_POS | O53: EVENT_STEP | P53: HQ_SERVER | Q53: POS_SYSTEM_DATE | R53: POS_SYSTEM_TIME | S53: LOG_FILE_ID
A55: 53810126 | B55: 087 | C55: 00 | D55: 14026295 | E55: GEODataExchange | F55: true | G55: 100 | H55: 2020/09/14 | I55: 02:22:52 | J55: 09/09/2020 | K55: 11:56:14 | L55: 0555502 | M55: 1 | P55: 10.182.247.103 | Q55: 2020/09/14 | R55: 02:22:52 | S55: csonlapqa02.30680325
A56: 53810127 | B56: CS | C56: S | D56: 14026296 | E56: GEODataExchange | F56: true | G56: 100 | H56: 2020/09/14 | I56: 02:22:52 | J56: 09/09/2020 | K56: 11:56:14 | L56: 0555502 | M56: 1 | P56: 10.182.247.103 | Q56: 2020/09/14 | R56: 02:22:52 | S56: csonlapqa02.30680325
A57: 53810136 | B57: 087 | C57: 01 | D57: 14026295 | E57: GEODataExchangeConfirm | F57: true | G57: 100 | H57: 2020/09/14 | I57: 02:23:28 | J57: 09/09/2020 | K57: 11:57:48 | L57: 0555502 | M57: 3 | P57: 10.182.247.103 | Q57: 2020/09/14 | R57: 02:23:28 | S57: csonlapqa02.30680329
A58: 53810137 | B58: CS | C58: S | D58: 14026296 | E58: GEODataExchangeConfirm | F58: true | G58: 100 | H58: 2020/09/14 | I58: 02:23:28 | J58: 09/09/2020 | K58: 11:57:48 | L58: 0555502 | M58: 3 | P58: 10.182.247.103 | Q58: 2020/09/14 | R58: 02:23:28 | S58: csonlapqa02.30680329
A59: 53810579 | B59: 087 | C59: 01 | D59: 14026295 | E59: GEODataExchangeConfirm | F59: true | G59: 100 | H59: 2020/09/14 | I59: 02:23:28 | J59: 09/09/2020 | K59: 13:35:28 | L59: BF1ONLSTD | M59: 3 | N59: 117.113.122.167 | P59: 10.182.247.103 | Q59: 2020/09/14 | R59: 02:23:28 | S59: csonlapqa02.30680351
...

Sheet AutoResend
A2: AutoResend_Confirm (กรณีส่งหาผวจ.ไม่สำเร็จ เช่น ติดต่อผู้ว่าจ้างไม่ได้ , Timeout จากผู้ว่าจ้าง)
A4: ก่อนซ่อมรายการ
A5: FROM ONLSTD.WS_ONLINE_TX
A12: หลังซ่อมรายการ
A13: FROM ONLSTD.WS_ONLINE_TX
A20: FROM ONLSTD.WS_ONLINE_LOG
A30: LOG FILE
A35: AutoResend_Confirm (ส่ง Confirm ซ้ำ)
A36: เช่นกรณีผวจ.เป็น Status3 แล้ว แต่ระหว่างส่งข้อมูลกลับเกิด Time out ทำให้ฝั่ง CS ยังค้าง Status2 ==> ทดสอบโดย ทำรายการ Status = 3 แก้เป็น 2
A37: ก่อนซ่อมรายการ
A38: FROM ONLSTD.WS_ONLINE_TX
A39: TX_ID | B39: CLIENT_CODE | C39: SERVICE_CODE | D39: COUNTER_NO | E39: TERM_NO | F39: POS_TAX_ID | G39: SERVICE_RUN_NO | H39: RECORD_STATUS | I39: OPERATING_DATE_TIME | J39: CLIENT_SERVICE_NO | K39: CLIENT_SERVICE_RUNNO | L39: VAT_RATE | M39: AMOUNT_RECEIVED | N39: VAT_AMOUNT | O39: BILL_TYPE | P39: BILL_NO | Q39: CUSTOMER_NAME | R39: CUSTOMER_ADDR_1 | S39: CUSTOMER_ADDR_2 | T39: CUSTOMER_ADDR_3 | U39: CUSTOMER_TEL_NO | V39: REFERENCE_1 | W39: REFERENCE_2 | X39: REFERENCE_3 | Y39: REFERENCE_4 | Z39: REFERENCE_5 | AA39: REFERENCE_6 | AB39: REFERENCE_7 | AC39: COMM_PAID_CODE | AD39: ZONE | AE39: R_SERVICE_RUNNO | AF39: CANCEL_OPERATING | AG39: OPERATE_BY_STAFF | AH39: OPERATING_ROUND | AI39: TEL_CODE | AJ39: FILLER | AK39: TRX_TYPE | AL39: STATUS | AM39: SYSTEM_DATE_TIME | AN39: RETRY_COUNT | AO39: SENDMAIL_COUNT | AP39: PAYMENT_CHANNEL | AQ39: TRANSACTION_ID | AR39: CLIENT_CODE_FR | AS39: SERVICE_CODE_FR | AT39: RETRY_COUNT_CANCEL | AU39: TIMEOUT_COUNT_CANCEL | AV39: AMOUNT_RECEIVED_VENDOR | AW39: VAT_AMOUNT_VENDOR | AX39: POS_SYSTEM_DATE_TIME | AY39: REFERENCE_9 | AZ39: CANCEL_ID | BA39: RETURN1 | BB39: RETURN2 | BC39: RETURN3 | BD39: COUPON_STATUS | BE39: CUSTOMER_TAX_ID | BF39: CUSTOMER_BRANCH_CODE | BG39: CUSTOMER_RECEIPT_NAME | BH39: CUSTOMER_RECEIPT_ADDR | BI39: OFFLINE_TXN | BJ39: ITOUCH_COUNTER_NO | BK39: ITOUCH_TERM_NO | BL39: ITOUCH_PAYMENT_CHANNEL
A41: 14026370 | B41: 087 | C41: 01 | D41: 11104 | E41: 1 | F41: 1110412345678 | G41: 000036 | H41: A | I41: 14/9/2020 4:34:49 | J41: 01 | K41: 000003 | L41: 7.0 | M41: 500 | N41: 32.71 | O41: E | P41: 3 | V41: 5100110108640 | W41: 0718352277370 | X41: NOBILL | Y41: REALTIME | AD41: 1 | AG41: 0555502 | AH41: 1 | AK41: N | AL41: 2 | AM41: 9/9/2020 14:08:21 | AN41: 8 | AP41: C05 | AU41: 0 | AX41: 14/9/2020 4:34:49
A42: 14026371 | B42: CS | C42: S | D42: 11104 | E42: 1 | F42: 1110412345678 | G42: 000037 | H42: A | I42: 14/9/2020 4:34:49 | J42: CS | K42: 000011 | L42: 7.0 | M42: 15 | N42: 0.98 | O42: B | P42: 11 | V42: 3011106624 | W42: 01 | X42: 14026370 | AD42: 1 | AG42: 0555502 | AH42: 1 | AK42: N | AL42: 3 | AM42: 9/9/2020 14:08:21 | AN42: 8 | AP42: C05 | AU42: 0 | AX42: 14/9/2020 4:34:49
A45: หลังซ่อมรายการ
A46: FROM ONLSTD.WS_ONLINE_TX
A47: TX_ID | B47: CLIENT_CODE | C47: SERVICE_CODE | D47: COUNTER_NO | E47: TERM_NO | F47: POS_TAX_ID | G47: SERVICE_RUN_NO | H47: RECORD_STATUS | I47: OPERATING_DATE_TIME | J47: CLIENT_SERVICE_NO | K47: CLIENT_SERVICE_RUNNO | L47: VAT_RATE | M47: AMOUNT_RECEIVED | N47: VAT_AMOUNT | O47: BILL_TYPE | P47: BILL_NO | Q47: CUSTOMER_NAME | R47: CUSTOMER_ADDR_1 | S47: CUSTOMER_ADDR_2 | T47: CUSTOMER_ADDR_3 | U47: CUSTOMER_TEL_NO | V47: REFERENCE_1 | W47: REFERENCE_2 | X47: REFERENCE_3 | Y47: REFERENCE_4 | Z47: REFERENCE_5 | AA47: REFERENCE_6 | AB47: REFERENCE_7 | AC47: COMM_PAID_CODE | AD47: ZONE | AE47: R_SERVICE_RUNNO | AF47: CANCEL_OPERATING | AG47: OPERATE_BY_STAFF | AH47: OPERATING_ROUND | AI47: TEL_CODE | AJ47: FILLER | AK47: TRX_TYPE | AL47: STATUS | AM47: SYSTEM_DATE_TIME | AN47: RETRY_COUNT | AO47: SENDMAIL_COUNT | AP47: PAYMENT_CHANNEL | AQ47: TRANSACTION_ID | AR47: CLIENT_CODE_FR | AS47: SERVICE_CODE_FR | AT47: RETRY_COUNT_CANCEL | AU47: TIMEOUT_COUNT_CANCEL | AV47: AMOUNT_RECEIVED_VENDOR | AW47: VAT_AMOUNT_VENDOR | AX47: POS_SYSTEM_DATE_TIME | AY47: REFERENCE_9 | AZ47: CANCEL_ID | BA47: RETURN1 | BB47: RETURN2 | BC47: RETURN3 | BD47: COUPON_STATUS | BE47: CUSTOMER_TAX_ID | BF47: CUSTOMER_BRANCH_CODE | BG47: CUSTOMER_RECEIPT_NAME | BH47: CUSTOMER_RECEIPT_ADDR | BI47: OFFLINE_TXN | BJ47: ITOUCH_COUNTER_NO | BK47: ITOUCH_TERM_NO | BL47: ITOUCH_PAYMENT_CHANNEL
A49: 14026370 | B49: 087 | C49: 01 | D49: 11104 | E49: 1 | F49: 1110412345678 | G49: 000036 | H49: A | I49: 14/9/2020 4:34:49 | J49: 01 | K49: 000003 | L49: 7.0 | M49: 500.00 | N49: 32.71 | O49: E | P49: 3 | V49: 5100110108640 | W49: 0718352277370 | X49: NOBILL | Y49: REALTIME | AD49: 1 | AG49: BF2ONLSTD | AH49: 1 | AK49: N | AL49: 3 | AM49: 9/9/2020 14:13:43 | AN49: 8 | AP49: C05 | AU49: 0 | AX49: 14/9/2020 4:34:49
A50: 14026371 | B50: CS | C50: S | D50: 11104 | E50: 1 | F50: 1110412345678 | G50: 000037 | H50: A | I50: 14/9/2020 4:34:49 | J50: CS | K50: 000011 | L50: 7.0 | M50: 15 | N50: 0.98 | O50: B | P50: 11 | V50: 3011106624 | W50: 01 | X50: 14026370 | AD50: 1 | AG50: 0555502 | AH50: 1 | AK50: N | AL50: 3 | AM50: 9/9/2020 14:08:21 | AN50: 8 | AP50: C05 | AU50: 0 | AX50: 14/9/2020 4:34:49
A53: FROM ONLSTD.WS_ONLINE_LOG
A54: LOG_ID | B54: CLIENT_CODE | C54: SERVICE_CODE | D54: TX_ID | E54: EVENT | F54: SUCCESS | G54: CODE | H54: BUSINESS_DATE | I54: BUSINESS_TIME | J54: SYSTEM_DATE | K54: SYSTEM_TIME | L54: USER_ID | M54: STATUS | N54: DB_IP_POS | O54: EVENT_STEP | P54: HQ_SERVER | Q54: POS_SYSTEM_DATE | R54: POS_SYSTEM_TIME | S54: LOG_FILE_ID
A56: 53810814 | B56: 087 | C56: 00 | D56: 14026370 | E56: GEODataExchange | F56: true | G56: 100 | H56: 2020/09/14 | I56: 04:34:49 | J56: 09/09/2020 | K56: 14:08:01 | L56: 0555502 | M56: 1 | P56: 10.182.247.103 | Q56: 2020/09/14 | R56: 04:34:49 | S56: csonlapqa02.30680463
A57: 53810815 | B57: CS | C57: S | D57: 14026371 | E57: GEODataExchange | F57: true | G57: 100 | H57: 2020/09/14 | I57: 04:34:49 | J57: 09/09/2020 | K57: 14:08:01 | L57: 0555502 | M57: 1 | P57: 10.182.247.103 | Q57: 2020/09/14 | R57: 04:34:49 | S57: csonlapqa02.30680463
A58: 53810817 | B58: 087 | C58: 01 | D58: 14026370 | E58: GEODataExchangeConfirm | F58: true | G58: 100 | H58: 2020/09/14 | I58: 04:35:11 | J58: 09/09/2020 | K58: 14:08:21 | L58: 0555502 | M58: 3 | P58: 10.182.247.103 | Q58: 2020/09/14 | R58: 04:35:11 | S58: csonlapqa02.30680465
A59: 53810818 | B59: CS | C59: S | D59: 14026371 | E59: GEODataExchangeConfirm | F59: true | G59: 100 | H59: 2020/09/14 | I59: 04:35:11 | J59: 09/09/2020 | K59: 14:08:21 | L59: 0555502 | M59: 3 | P59: 10.182.247.103 | Q59: 2020/09/14 | R59: 04:35:11 | S59: csonlapqa02.30680465
A60: 53810846 | B60: 087 | C60: 01 | D60: 14026370 | E60: GEODataExchangeConfirm | F60: true | G60: 100 | H60: 2020/09/14 | I60: 04:34:49 | J60: 09/09/2020 | K60: 14:13:43 | L60: BF2ONLSTD | M60: 3 | P60: 10.182.247.103 | Q60: 2020/09/14 | R60: 04:34:49 | S60: csonlapqa02.30680483
A63: LOG FILE
A68: AutoResend_ORConfirm ทำรายการ Status = 9 แก้เป็น 8
A70: ก่อนซ่อมรายการ
A71: FROM ONLSTD.WS_ONLINE_TX
A72: TX_ID | B72: CLIENT_CODE | C72: SERVICE_CODE | D72: COUNTER_NO | E72: TERM_NO | F72: POS_TAX_ID | G72: SERVICE_RUN_NO | H72: RECORD_STATUS | I72: OPERATING_DATE_TIME | J72: CLIENT_SERVICE_NO | K72: CLIENT_SERVICE_RUNNO | L72: VAT_RATE | M72: AMOUNT_RECEIVED | N72: VAT_AMOUNT | O72: BILL_TYPE | P72: BILL_NO | Q72: CUSTOMER_NAME | R72: CUSTOMER_ADDR_1 | S72: CUSTOMER_ADDR_2 | T72: CUSTOMER_ADDR_3 | U72: CUSTOMER_TEL_NO | V72: REFERENCE_1 | W72: REFERENCE_2 | X72: REFERENCE_3 | Y72: REFERENCE_4 | Z72: REFERENCE_5 | AA72: REFERENCE_6 | AB72: REFERENCE_7 | AC72: COMM_PAID_CODE | AD72: ZONE | AE72: R_SERVICE_RUNNO | AF72: CANCEL_OPERATING | AG72: OPERATE_BY_STAFF | AH72: OPERATING_ROUND | AI72: TEL_CODE | AJ72: FILLER | AK72: TRX_TYPE | AL72: STATUS | AM72: SYSTEM_DATE_TIME | AN72: RETRY_COUNT | AO72: SENDMAIL_COUNT | AP72: PAYMENT_CHANNEL | AQ72: TRANSACTION_ID | AR72: CLIENT_CODE_FR | AS72: SERVICE_CODE_FR | AT72: RETRY_COUNT_CANCEL | AU72: TIMEOUT_COUNT_CANCEL | AV72: AMOUNT_RECEIVED_VENDOR | AW72: VAT_AMOUNT_VENDOR | AX72: POS_SYSTEM_DATE_TIME | AY72: REFERENCE_9 | AZ72: CANCEL_ID | BA72: RETURN1 | BB72: RETURN2 | BC72: RETURN3 | BD72: COUPON_STATUS | BE72: CUSTOMER_TAX_ID | BF72: CUSTOMER_BRANCH_CODE | BG72: CUSTOMER_RECEIPT_NAME | BH72: CUSTOMER_RECEIPT_ADDR | BI72: OFFLINE_TXN | BJ72: ITOUCH_COUNTER_NO | BK72: ITOUCH_TERM_NO | BL72: ITOUCH_PAYMENT_CHANNEL
A74: 14026338 | B74: 087 | C74: 01 | D74: 11104 | E74: 1 | F74: 1110412345678 | G74: 000032 | H74: A | I74: 14/9/2020 4:20:41 | J74: 01 | K74: 000002 | L74: 7.0 | M74: 300 | N74: 19.63 | O74: E | P74: 2 | V74: 5100110108640 | W74: 0718352277370 | X74: NOBILL | Y74: REALTIME | AD74: 1 | AG74: 0555502 | AH74: 1 | AK74: N | AL74: 3 | AM74: 9/9/2020 13:55:05 | AN74: 8 | AP74: C05 | AU74: 0 | AX74: 14/9/2020 4:20:41
A75: 14026339 | B75: CS | C75: S | D75: 11104 | E75: 1 | F75: 1110412345678 | G75: 000033 | H75: A | I75: 14/9/2020 4:20:41 | J75: CS | K75: 000010 | L75: 7.0 | M75: 15 | N75: 0.98 | O75: B | P75: 10 | V75: 3011106624 | W75: 01 | X75: 14026338 | AD75: 1 | AG75: 0555502 | AH75: 1 | AK75: N | AL75: 3 | AM75: 9/9/2020 13:55:05 | AN75: 8 | AP75: C05 | AU75: 0 | AX75: 14/9/2020 4:20:41
A76: 14026340 | B76: 087 | C76: 01 | D76: 11104 | E76: 1 | F76: 1110412345678 | G76: 000034 | H76: C | I76: 14/9/2020 4:20:41 | J76: 01 | K76: 000002 | L76: 7.0 | M76: -300.00 | N76: -19.63 | O76: E | P76: 2 | V76: 5100110108640 | W76: 0718352277370 | X76: NOBILL | Y76: REALTIME | AD76: 1 | AE76: 14026338 | AF76: 9/9/2020 13:55:43 | AG76: BF1ONLSTD | AH76: 1 | AK76: R | AL76: 8 | AM76: 9/9/2020 13:59:42 | AN76: 8 | AP76: C05 | AU76: 0
A77: 14026341 | B77: CS | C77: S | D77: 11104 | E77: 1 | F77: 1110412345678 | G77: 000035 | H77: C | I77: 14/9/2020 4:20:41 | J77: CS | K77: 000010 | L77: 7.0 | M77: -15 | N77: -0.98 | O77: B | P77: 10 | V77: 3011106624 | W77: 01 | X77: 14026338 | AD77: 1 | AE77: 14026339 | AF77: 9/9/2020 13:55:43 | AG77: 0555502 | AH77: 1 | AK77: R | AL77: 9 | AM77: 9/9/2020 13:55:55 | AN77: 8 | AP77: C05 | AU77: 0
A81: หลังซ่อมรายการ
A82: FROM ONLSTD.WS_ONLINE_TX
A83: TX_ID | B83: CLIENT_CODE | C83: SERVICE_CODE | D83: COUNTER_NO | E83: TERM_NO | F83: POS_TAX_ID | G83: SERVICE_RUN_NO | H83: RECORD_STATUS | I83: OPERATING_DATE_TIME | J83: CLIENT_SERVICE_NO | K83: CLIENT_SERVICE_RUNNO | L83: VAT_RATE | M83: AMOUNT_RECEIVED | N83: VAT_AMOUNT | O83: BILL_TYPE | P83: BILL_NO | Q83: CUSTOMER_NAME | R83: CUSTOMER_ADDR_1 | S83: CUSTOMER_ADDR_2 | T83: CUSTOMER_ADDR_3 | U83: CUSTOMER_TEL_NO | V83: REFERENCE_1 | W83: REFERENCE_2 | X83: REFERENCE_3 | Y83: REFERENCE_4 | Z83: REFERENCE_5 | AA83: REFERENCE_6 | AB83: REFERENCE_7 | AC83: COMM_PAID_CODE | AD83: ZONE | AE83: R_SERVICE_RUNNO | AF83: CANCEL_OPERATING | AG83: OPERATE_BY_STAFF | AH83: OPERATING_ROUND | AI83: TEL_CODE | AJ83: FILLER | AK83: TRX_TYPE | AL83: STATUS | AM83: SYSTEM_DATE_TIME | AN83: RETRY_COUNT | AO83: SENDMAIL_COUNT | AP83: PAYMENT_CHANNEL | AQ83: TRANSACTION_ID | AR83: CLIENT_CODE_FR | AS83: SERVICE_CODE_FR | AT83: RETRY_COUNT_CANCEL | AU83: TIMEOUT_COUNT_CANCEL | AV83: AMOUNT_RECEIVED_VENDOR | AW83: VAT_AMOUNT_VENDOR | AX83: POS_SYSTEM_DATE_TIME | AY83: REFERENCE_9 | AZ83: CANCEL_ID | BA83: RETURN1 | BB83: RETURN2 | BC83: RETURN3 | BD83: COUPON_STATUS | BE83: CUSTOMER_TAX_ID | BF83: CUSTOMER_BRANCH_CODE | BG83: CUSTOMER_RECEIPT_NAME | BH83: CUSTOMER_RECEIPT_ADDR | BI83: OFFLINE_TXN | BJ83: ITOUCH_COUNTER_NO | BK83: ITOUCH_TERM_NO | BL83: ITOUCH_PAYMENT_CHANNEL
A85: 14026338 | B85: 087 | C85: 01 | D85: 11104 | E85: 1 | F85: 1110412345678 | G85: 000032 | H85: A | I85: 14/9/2020 4:20:41 | J85: 01 | K85: 000002 | L85: 7.0 | M85: 300 | N85: 19.63 | O85: E | P85: 2 | V85: 5100110108640 | W85: 0718352277370 | X85: NOBILL | Y85: REALTIME | AD85: 1 | AG85: 0555502 | AH85: 1 | AK85: N | AL85: 3 | AM85: 9/9/2020 13:55:05 | AN85: 8 | AP85: C05 | AU85: 0 | AX85: 14/9/2020 4:20:41
A86: 14026339 | B86: CS | C86: S | D86: 11104 | E86: 1 | F86: 1110412345678 | G86: 000033 | H86: A | I86: 14/9/2020 4:20:41 | J86: CS | K86: 000010 | L86: 7.0 | M86: 15 | N86: 0.98 | O86: B | P86: 10 | V86: 3011106624 | W86: 01 | X86: 14026338 | AD86: 1 | AG86: 0555502 | AH86: 1 | AK86: N | AL86: 3 | AM86: 9/9/2020 13:55:05 | AN86: 8 | AP86: C05 | AU86: 0 | AX86: 14/9/2020 4:20:41
...

Sheet Notes
A1: Notes
A3: Mail Confirm Error Code
B6: Click =>

Sheet How to use template
A1: TEST CASES & RESULT
A2: TEST DESCRIPTION | G2: TEST ENVIRONMENT หากกำหนดEnvironmentไว้ใน Test Plan ไม่ต้องใส่รายละเอียด | K2: Priority Type | L2: Count Priority
A3: PROJECT/SR CODE: | D3: ระบุ Project ID เช่น GO0145 | G3: TEST ENVIRONMENT ID: | H3: ระบุเลขที่ของ Environment ตามTest Plan | K3: Priority - 1 | L3: Count จำนวน Priority (P1) ในการทดสอบ
A4: PROJECT NAME/ SR DETAIL: | D4: ระบุชื่อ Project เช่น 7 Online Top up…. | G4: ENVIRONMENT: | H4: Client/Server | K4: Priority - 2 | L4: Count จำนวน Priority (P2) ในการทดสอบ
A5: TEST PHASE: | D5: Integration | E5: OTHERS : | G5: PC/NOTEBOOK CAPABILITIES: | H5: Memory: | J5: Harddisk: | K5: Priority - 3 | L5: Count จำนวน Priority (P3) ในการทดสอบ
A6: TEST CASE NO.: | D6: ระบุเลขที่ Test Case | E6: VERSION : | F6: ระบุ Version/ Revision ของ Test Case | G6: CPU Speed: | H6: Others
A7: TEST CASE NAME : | D7: ระบุชื่อTest Case หรืออาจเป็นคำอธิบาย | G7: SERVER CAPABILITIES: | H7: Memory: | J7: Harddisk:
A8: TEST OBJECTIVE: | D8: ใส่วัตถุประสงค์ในการทดสอบ | G8: CPU Speed: | H8: Others
A9: TEST DATE: | D9: วันที่หรือช่วงวันที่ทำการทดสอบ | E9: NUMBER OF TESTING ROUND: | F9: ระบุว่าเป็นการทดสอบครั้งที่เท่าใด ในกรณีที่ใช้Test case เดิม | G9: DATABASE CAPABILITIES: | H9: Memory: | J9: Harddisk:
A10: PRE-CONDITION: | D10: ระบุเงื่อนไขก่อนทำการทดสอบ | G10: CPU Speed: | H10: Others
A11: SPECIAL NOTES: | D11: ระบุเงื่อนไขอื่น ๆ หรือสิ่งที่ผู้ทดสอบต้องระวังขณะทำการทดสอบ | G11: TEST DATA LOCATION: ระบุที่เก็บdata ที่ใช้ในการทดสอบ
A12: REFERENCE DOCUMENTS : | D12: ระบุเอกสารอ้างอิง เช่น USED CASES, MODULE, FORM REFERENCE, FUNCTIONAL SPECIFICATION | G12: OS : ระบุ OS ของเครื่องทดสอบ
A13: TOTAL TIME USED TO EXECUTE THIS TEST CASE: | D13: ใส่เวลาที่ใช้ในการทดสอบทั้งหมด | G13: WEB BROWSER : ระบุ Web browser และ Version ที่ใช้ในการทดสอบ เช่น Internet Explorer 11, Chrome) เป็นต้น หากไม่ได้ใช้ Web browser ในการทดสอบ ให้ระบุเป็น N/A
A14: PREPARED BY: | D14: ระบุชื่อผู้ทำเอกสาร | E14: REVIEWED BY: | F14: ระบุชื่อผู้Reviewเอกสาร | G14: (ถ้าไม่มีเลขที่อ้างอิงให้ใส่รายละเอียดมากเท่าที่จะสามารถทำได้)
A16: Step No | B16: Updated | C16: VP | D16: Test case / script | E16: Data | F16: Expected Results | G16: Actual Results | H16: Test Status | I16: Test time | J16: Reproduct/Remark
A18: เลขที่ลำดับขั้นตอน | B18: วันที่แก้ไขเปลี่ยนแปลงรายละเอียดTest case หรือExpected result | C18: Flag ระบุPriority สำหรับการทดสอบ | D18: คำอธิบายรายละเอียด หรือขั้นตอนการทดสอบ | E18: ระบุข้อมูลที่ใช้ในการทดสอบ หรือเลขที่ Scenerio | F18: ผลที่คาดว่าจะเกิดหลังจากทำตามScriptที่ระบุ | G18: ผลที่เกิดจริงหลังจากทำตามScriptที่ระบุ | H18: สรุปผลการทดสอบ Pass เมื่อผลเป็นไปตามที่คาดไว้ และ Fail เมื่อไม่เกิดตามที่คาดไว้ | I18: เวลาที่ใช้ในการทำตามScriptที่ระบุ | J18: ในกรณีที่พบDefectสามารถทำซ้ำได้หรือไม่/หมายเหตุเพิ่มเติมเพื่อประกอบความเข้าใจ
C19: P1/P2/P3 | H19: Pass / Fail
A21: Note:
A22: ในการทำการ save file test case ให้ save ตาม test case no เพื่อสะดวกในการตรวจสอบ
A23: Version และ Revision ของ Test Case นี้ เมื่อเริ่มสร้างครั้งแรกคือ 1.0 และเมื่อมีการเปลี่ยนปลงจาก change request ต่าง ๆ ก็ปรับเป็น 1.1, 1.2 กรณีที่มีการเปลี่ยนแปลงโดยที่ขั้นตอนการทดสอบต้องแก้ไขใหม่หมด แต่ผลลัพธ์เหมือนเดิม ให้ทำการเปลี่ยน Version เป็น 2, 3 ได้
A25: Priority คือ
A26: Priority - 1 (P1) : Allocated to all tests that must be executed in any case.
A27: Priority - 2 (P2) : Allocated to the tests which can be executed, only when time permits.
A28: Priority - 3 (P3) : Allocated to the tests, which even if not executed, will not cause big upsets.

Sheet Option
A1: PROJECT/SR CODE | B1: Test Date | C1: Version | D1: รายละเอียด | E1: Mandays | F1: ผู้ทดสอบ | G1: Remark | H1: Solution ในการพัฒนาระบบ | I1: OR | J1: REPRINT | K1: UPLOAD | L1: DEL-UPLOAD | M1: MIN | N1: MAX | O1: ค่าบริการ กรุงเทพ | P1: ค่าบริการ ต่างจังหวัด | Q1: CHK_AMT | R1: check Dup
A2: {=INDEX('SR History'!A:A,COUNTA('SR History'!A:A)+1)} -> CP ALL GROUP-2025/03746 | B2: {=INDEX('SR History'!B:B,COUNTA('SR History'!B:B)+2)} -> 244236 | C2: {=INDEX('SR History'!C:C,COUNTA('SR History'!C:C)+2)} -> 25009A | D2: {=INDEX('SR History'!D:D,COUNTA('SR History'!D:D)+2)} -> New Client 10972_กรุงเทพมหานคร (Owner AE : Thanat-On N. / BA : Arreeya S. , Channel : POS, SAMEDAY, BACKEND) - Service 01-50 ชำระค่าขยะ - ระบบ Full online - Memo : CS-BUD3 642/2568 - มีผลวันที่ 28 สิงหาคม 2568 - อ้างอิงเอกสาร => 10972_กรุงเทพมหานครV0.4.xlsx | E2: {=INDEX('SR History'!E:E,COUNTA('SR History'!E:E)+2)} -> 2 MD | F2: {=INDEX('SR History'!F:F,COUNTA('SR History'!F:F)+2)} -> Nakarin S. | G2: {=INDEX('SR History'!G:G,COUNTA('SR History'!G:G)+2)} -> New Full | H2: {=INDEX('SR History'!H:H,COUNTA('SR History'!H:H)+2)} -> 0 | I2: {=INDEX('SR History'!I:I,COUNTA('SR History'!I:I)+1)} -> 10800 | J2: {=INDEX('SR History'!J:J,COUNTA('SR History'!J:J)+2)} -> 0 | K2: {=INDEX('SR History'!K:K,COUNTA('SR History'!K:K)+1)} -> N | L2: {=INDEX('SR History'!L:L,COUNTA('SR History'!L:L)+2)} -> N | M2: {=INDEX('SR History'!M:M,COUNTA('SR History'!M:M)+1)} -> 1 | N2: {=INDEX('SR History'!N:N,COUNTA('SR History'!N:N)+2)} -> 90000 | O2: {=INDEX('SR History'!O:O,COUNTA('SR History'!O:O)+1)} -> 10,20 | P2: {=INDEX('SR History'!P:P,COUNTA('SR History'!P:P)+1)} -> 10,21 | Q2: {=INDEX('SR History'!Q:Q,COUNTA('SR History'!Q:Q)+2)} -> ไม่รองรับทศนิยม | R2: {=INDEX('SR History'!R:R,COUNTA('SR History'!R:R)+2)} -> Online Check
A4: Test Phase | B4: Test Priority | C4: Test Environment
A5: Unit | B5: High | C5: Stand Alone
A6: Integration | B6: Medium | C6: Client/Server
A7: System | B7: Low | C7: Web Browser
A8: UAT
A9: Other, Please specify
A11: 1 | B11: 1 หมายถึง กำหนดค่าบริการตาม WS_CLIENT_CHARGE
A12: 2 | B12: 2 หมายถึง กำหนดค่าบริการเป็นขั้นตาม WS_CLIENT_CHARGE_STEP
A13: 3 | B13: 3 หมายถึง กำหนดค่าบริการเป็นขั้นตาม WS_CLIENT_CHARGE_STEP เหมือนกัน แต่เอาค่าเงินที่ได้จากตอนที่ ผวจ. ตอบกลับมา มาคิดว่าอยู่ในช่วงไหน
A14: 4 | B14: 4 หมายถึง คิดค่าบริการแบบรวม แต่ละ transaction
A15: N | B15: N หมายถึง ไม่คิดค่าบริการ
A16: M | B16: M หมายถึง รองรับค่าบริการแบบว่าส่งหลาย ๆ Vendor กลับไปหาร้าน
A18: Y | B18: Y = แก้ไขเงินได้
A19: N | B19: N = แก้ไขเงินไม่ได้
A21: 1 | B21: 1 = "ไม่"รองรับทศนิยม รับเฉพาะ 0.00 เท่านั้น
A22: 2 | B22: 2 = รองรับ"ลงตัว" 0.00 , 0.25, 0.50 , 0.75
A23: N | B23: N = รองรับทศนิยม "ไม่" ลงตัว 0.00,0.01,...0.99
